Workbook

Sheet AplicQuest
A1: Processo | B1: DtDisp | C1: Juiz | D1: Vara | E1: Nome | F1: Local | G1: Sexo | H1: DN | I1: Cutis | J1: Cabelo | K1: Objetos | L1: Maconha | M1: Cocaína | N1: Crack | O1: Ecstasy | P1: LSD | Q1: Outras | R1: DenDrog | S1: DenOutros | T1: Aspectos | U1: Sentença | V1: ResDrogas | W1: ResOutros | X1: AvalNegPB | Y1: PenaBase | Z1: Agravantes33 | AA1: Atenuantes33 | AB1: Aumento33 | AC1: §4º | AD1: Pena33 | AE1: PenaDrogas | AF1: PenaOutros | AG1: TotPen | AH1: Substituição da pena | AI1: Regime inicial
A2: 00755542920168260050 | B2: 17/10/2017 | C2: Antonio Carlos de Campos Machado Junior | D2: 19ª Vara Criminal | E2: JUNIERE CASTRO DA SILVA | F2: Via Pública | G2: Masculino | H2: 34226 | I2: Parda | J2: Liso | K2: Pochete. Papéis . Celular. Dinheiro R$ 70,00 | L2: 20 porções. 17,9 g | M2: 33 porções. 16,6 g | N2: 27 porções. 3,95 g | O2: 0 | P2: 0 | Q2: 0 | R2: Art. 33 | S2: Não | T2: Divergências nos relatos dos policiais. Local de tráfico. Confissão informal. Preso no momento da sentença | U2: Procedente | V2: Art. 33 | W2: NA | X2: Não | Y2: 5a | Z2: Não | AA2: Não | AB2: Não | AC2: Sim total | AD2: 1a 8m | AE2: NA | AF2: NA | AG2: 1a 8m | AH2: Sim | AI2: NA
A3: 00646328920178260050 | B3: 19/10/2017 | C3: Antonio Carlos de Campos Machado Junior | D3: 19ª Vara Criminal | E3: VITOR CESAR DE OLIVEIRA ROCHA | F3: Favela - Viela | G3: Masculino | H3: 36283 | I3: Parda | J3: Outros | K3: Bolsa. Papéis. Dinheiro R$ 16,00 | L3: 67 porções. 180 g | M3: 155 porções. 198 g | N3: 0 | O3: 0 | P3: 0 | Q3: 0 | R3: Art. 33 | S3: Não | T3: Confissão. Local de tráfico. Preso no momento da sentença | U3: Procedente | V3: Art. 33 | W3: NA | X3: Não | Y3: 5a | Z3: Não | AA3: Não | AB3: Não | AC3: Sim parcial | AD3: 2a | AE3: NA | AF3: NA | AG3: 2a | AH3: Sim | AI3: NA
A4: 01006793320158260050 | B4: 14/03/2017 | C4: Antonio Carlos de Campos Machado Junior | D4: 19ª Vara Criminal | E4: ERIC RICARDO DA SILVA | F4: Via Pública | G4: Masculino | H4: 32120 | I4: Parda | J4: Não disponível | K4: Pochete | L4: 1 porção. 1 g | M4: 135 porções. 135 g | N4: 0 | O4: 0 | P4: 0 | Q4: 0 | R4: Art. 33 | S4: Não | T4: Divergências nos relatos dos policiais | U4: Desclassificação | V4: Art. 28 | W4: NA | X4: NA | Y4: NA | Z4: NA | AA4: NA | AB4: NA | AC4: NA | AD4: NA | AE4: Não | AF4: NA | AG4: NA | AH4: NA | AI4: NA
A5: 00198188920178260050 | B5: 06/06/2017 | C5: Antonio Carlos de Campos Machado Junior | D5: 19ª Vara Criminal | E5: ELENIDIO MESSIAS DE JESUS | F5: Via Pública | G5: Masculino | H5: 31345 | I5: Branca | J5: Calvície total | K5: Veículo | L5: 600 porções. 811,6 g | M5: 550 porções. 233,5 g | N5: 2800 porções. 604,6 g | O5: 0 | P5: 0 | Q5: Lança-perfume. 200 frascos. 1600 ml | R5: Art. 33 | S5: Não | T5: Confissão. Preso no momento da sentença | U5: Procedente | V5: Art. 33 | W5: NA | X5: Sim. Circunstâncias. Quantidade | Y5: 6a 3m | Z5: Não | AA5: Confissão | AB5: Não | AC5: Não cabimento | AD5: 6a 3m | AE5: NA | AF5: NA | AG5: 6a 3m | AH5: NA | AI5: Fechado
A6: 00243129420178260050 | B6: 20/09/2017 | C6: Antonio Carlos de Campos Machado Junior | D6: 19ª Vara Criminal | E6: Ivo Rodrigues de Lima | F6: Residência | G6: Masculino | H6: 28579 | I6: Branca | J6: Ondulado | K6: Peneira. Colher. Caixa térmica. Balança. Caderno. Celular. Faca. Bacia | L6: 4 sacos. 1 tijolo. 842,2 (total) | M6: 1 saco. 291,7 g | N6: 160 porções. 9 tijolos. 1961,4 g (total) | O6: 0 | P6: 0 | Q6: 0 | R6: Art. 33. Art. 35 | S6: Não | T6: Preso no momento da sentença. Denúncia | U6: Parcialmente procedente | V6: Art. 33 | W6: NA | X6: Não | Y6: 5a | Z6: Não | AA6: Não | AB6: Não | AC6: Sim parcial | AD6: 4a | AE6: NA | AF6: NA | AG6: 4a | AH6: Não | AI6: Fechado
A7: 00243129420178260050 | B7: 20/09/2017 | C7: Antonio Carlos de Campos Machado Junior | D7: 19ª Vara Criminal | E7: Marcelo Gomes de Sousa | F7: Residência | G7: Masculino | H7: 34806 | I7: Branca | J7: Ondulado | K7: Nada | L7: 4 sacos. 1 tijolo. 842,2 (total) | M7: 1 saco. 291,7 g | N7: 160 porções. 9 tijolos. 1961,4 g (total) | O7: 0 | P7: 0 | Q7: 0 | R7: Art. 33. Art. 35 | S7: Não | T7: Preso no momento da sentença | U7: Absolvição | V7: NA | W7: NA | X7: NA | Y7: NA | Z7: NA | AA7: NA | AB7: NA | AC7: NA | AD7: NA | AE7: NA | AF7: NA | AG7: NA | AH7: NA | AI7: NA
A8: 00850022620168260050 | B8: 24/01/2017 | C8: Antonio Carlos de Campos Machado Junior | D8: 19ª Vara Criminal | E8: Henrique dos Santos | F8: Residência | G8: Masculino | H8: 32087 | I8: Branca | J8: Não disponível | K8: Dinheiro R$ 370,00 | L8: 20 porções. 34,2 g | M8: 66 porções. 4,1 g | N8: 80 porções. 2,3 g | O8: 0 | P8: 0 | Q8: 0 | R8: Art. 33 | S8: Não | T8: Preso no momento da sentença | U8: Procedente | V8: Art. 33 | W8: NA | X8: Não | Y8: 5a | Z8: Não | AA8: Não | AB8: Não | AC8: Não cabimento | AD8: 5a | AE8: NA | AF8: NA | AG8: 5a | AH8: NA | AI8: Fechado
A9: 00199439120168260050 | B9: 30/03/2017 | C9: Vivian Brenner De Oliveira | D9: 11ª Vara Criminal | E9: TIAGO SILVA SOARES | F9: Área não ocupada | G9: Masculino | H9: 33476 | I9: Preta | J9: Carapinha | K9: Dinheiro R$ 24,00 | L9: 0 | M9: 0 | N9: 25 porções. 5,5 g | O9: 0 | P9: 0 | Q9: 0 | R9: Art. 33 | S9: Não | T9: Local de tráfico. Confissão. Confissão informal | U9: Procedente | V9: Art. 33 | W9: NA | X9: Não | Y9: 5a | Z9: Não | AA9: Não | AB9: Não | AC9: Sim parcial | AD9: 3a 4m | AE9: NA | AF9: NA | AG9: 3a 4m | AH9: Não | AI9: Fechado
A10: 00959728520168260050 | B10: 17/03/2017 | C10: Lizianne Marques Curto | D10: 11ª Vara Criminal | E10: RENATO DA SILVA GOMES | F10: Via Pública | G10: Masculino | H10: 32525 | I10: Parda | J10: Encaracolado | K10: Dinheiro R$ 39,00 | L10: 20 porções. 35,8 g | M10: 259 porções. 158,8 g | N10: 0 | O10: 0 | P10: 0 | Q10: 0 | R10: Art. 33 | S10: Não | T10: Local de tráfico. Preso no momento da sentença. Confissão informal | U10: Procedente | V10: Art. 33 | W10: NA | X10: Sim. Natureza. Quantidade | Y10: 6a | Z10: Reincidência | AA10: Não | AB10: Não | AC10: Não cabimento | AD10: 7a | AE10: NA | AF10: NA | AG10: 7a | AH10: NA | AI10: Fechado
A11: 00461275020178260050 | B11: 04/09/2017 | C11: Rejane Rodrigues Lage | D11: 11ª Vara Criminal | E11: RAFAEL SANTANA NUNES BEZERRA | F11: Residência | G11: Masculino | H11: 34009 | I11: Parda | J11: Não disponível | K11: Arma de fogo. Cartuchos. Capacete. Celular | L11: 0 | M11: 103 porções. 46,2 g | N11: 0 | O11: 0 | P11: 0 | Q11: 0 | R11: Art. 33 | S11: Art. 16 L10826 | T11: Preso no momento da sentença. Divergências nos relatos dos policiais | U11: Absolvição | V11: NA | W11: NA | X11: NA | Y11: NA | Z11: NA | AA11: NA | AB11: NA | AC11: NA | AD11: NA | AE11: NA | AF11: NA | AG11: NA | AH11: NA | AI11: NA
A12: 00607549320168260050 | B12: 21/03/2017 | C12: Vivian Brenner De Oliveira | D12: 11ª Vara Criminal | E12: ADEMIR LAMEU DA SILVA | F12: Via Pública | G12: Masculino | H12: 32784 | I12: Branca | J12: Encaracolado | K12: Dinheiro R$ 30,00 | L12: 0 | M12: 8 porções. 5,5 g | N12: 35 porções. 13,6 g | O12: 0 | P12: 0 | Q12: 0 | R12: Art. 33 | S12: Não | T12: Local de tráfico. Confissão informal | U12: Procedente | V12: Art. 33 | W12: NA | X12: Não | Y12: 5a | Z12: Não | AA12: Não | AB12: Não | AC12: Sim total | AD12: 1a 8m | AE12: NA | AF12: NA | AG12: 1a 8m | AH12: Não | AI12: Fechado
A13: 00116518320178260050 | B13: 04/07/2017 | C13: Tatiana Vieira Guerra | D13: 11ª Vara Criminal | E13: CICERO LEOPOLDINO DA SILVA | F13: Via Pública | G13: Masculino | H13: 26584 | I13: Preta | J13: Carapinha | K13: Papéis. Celular. Dinheiro R$ 628,25 | L13: 0 | M13: 51 porções. 39,6 g | N13: 0 | O13: 0 | P13: 0 | Q13: 0 | R13: Art. 33 | S13: Não | T13: Local de tráfico. Preso no momento da sentença. Confissão informal | U13: Procedente | V13: Art. 33 | W13: NA | X13: Não | Y13: 5a | Z13: Não | AA13: Não | AB13: Não | AC13: Não cabimento | AD13: 5a | AE13: NA | AF13: NA | AG13: 5a | AH13: NA | AI13: Fechado
A14: 00125207120168260635 | B14: 25/05/2017 | C14: Rejane Rodrigues Lage | D14: 11ª Vara Criminal | E14: RONALDO DO NASCIMENTO | F14: Via Pública | G14: Masculino | H14: 29853 | I14: Parda | J14: Não disponível | K14: Automóvel. Mochila. Sacos. Embalagens. Papéis. Dinheiro R$ 308,00 | L14: 0 | M14: 15 porções. 15 g | N14: 0 | O14: 0 | P14: 0 | Q14: 0 | R14: Art. 33. Art. 34 | S14: Não | T14: Preso no momento da sentença. Confissão informal | U14: Procedente | V14: Art. 33. Art. 34 | W14: NA | X14: Sim. Antecedentes | Y14: 5a 10m | Z14: Reincidência | AA14: Não | AB14: Não | AC14: Não cabimento | AD14: 6a 9m 20d | AE14: 4a 1m | AF14: NA | AG14: 10a 10m 20d | AH14: NA | AI14: Fechado
A15: 00894625620168260050 | B15: 04/09/2017 | C15: Vivian Brenner De Oliveira | D15: 11ª Vara Criminal | E15: ANDERSON BATISTA CRESPILHO | F15: Via Pública | G15: Masculino | H15: 33615 | I15: Branca | J15: Liso | K15: Celular. Dinheiro R$ 21,00 | L15: 17 porções. 51,5 g | M15: 156 porções. 111 g | N15: 0 | O15: 0 | P15: 0 | Q15: 0 | R15: Art. 33 | S15: Art. 180 CP | T15: Local de tráfico | U15: Procedente | V15: Art. 33 | W15: Art. 180 CP | X15: Não | Y15: 5a | Z15: Não | AA15: Não | AB15: Não | AC15: Sim parcial | AD15: 3a 4m | AE15: NA | AF15: 1a | AG15: 4a 4m | AH15: NA | AI15: Fechado
A16: 0031554-41.2016.8.26.0050 | B16: 42864 | C16: Carlos José Zulian | D16: 1ª Vara Criminal | E16: Klaus dos Santos Souza | F16: Via Pública | G16: Masculino | H16: 31815 | I16: Parda | J16: Carapinha | K16: Dinheiro R$ 100,00 | L16: 0 | M16: 21 porções. 5,8 g | N16: 0 | O16: 0 | P16: 0 | Q16: 0 | R16: Art. 33 | S16: Não | T16: Confissão | U16: Desclassificação | V16: Art. 28 | W16: NA | X16: NA | Y16: NA | Z16: NA | AA16: NA | AB16: NA | AC16: NA | AD16: NA | AE16: Não | AF16: NA | AG16: NA | AH16: NA | AI16: NA
A17: 0007839-58.2016.8.26.0635 | B17: 42871 | C17: MARIA PRISCILLA ERNANDES VEIGA OLIVEIRA | D17: 1ª Vara Criminal | E17: RINGLE DURVAL GLERIA | F17: Restaurante e afins | G17: Masculino | H17: 30746 | I17: Branca | J17: Liso | K17: Veículo. Mala. Celular. Dinheiro R$ 2404,00 | L17: 16 tijolos. 7816 g | M17: 0 | N17: 0 | O17: 0 | P17: 0 | Q17: 0 | R17: Art. 33. Art. 35 | S17: Não | T17: Preso no momento da sentença. Denúncia | U17: Procedente | V17: Art. 33. Art. 35 | W17: NA | X17: Não | Y17: 5a | Z17: Reincidência | AA17: Não | AB17: Não | AC17: Não cabimento | AD17: 6a 8m | AE17: 4a | AF17: NA | AG17: 10a 8m | AH17: NA | AI17: Fechado
A18: 0007839-58.2016.8.26.0635 | B18: 42871 | C18: MARIA PRISCILLA ERNANDES VEIGA OLIVEIRA | D18: 1ª Vara Criminal | E18: THIAGO TEIXEIRA DE LIMA | F18: Restaurante e afins | G18: Masculino | H18: 32255 | I18: Branca | J18: Não disponível | K18: Veículo. Mala. Celular. Dinheiro R$ 2404,00 | L18: 16 tijolos. 7816 g | M18: 0 | N18: 0 | O18: 0 | P18: 0 | Q18: 0 | R18: Art. 33. Art. 35 | S18: Não | T18: Preso no momento da sentença. Denúncia | U18: Procedente | V18: Art. 33. Art. 35 | W18: NA | X18: Não | Y18: 5a | Z18: Não | AA18: Não | AB18: Não | AC18: Não | AD18: 5a | AE18: 3a | AF18: NA | AG18: 8a | AH18: NA | AI18: Fechado
A19: 0007839-58.2016.8.26.0635 | B19: 42871 | C19: MARIA PRISCILLA ERNANDES VEIGA OLIVEIRA | D19: 1ª Vara Criminal | E19: JONATHAN ALVES PAIXÃO | F19: Restaurante e afins | G19: Masculino | H19: 34325 | I19: Branca | J19: Liso | K19: Veículo. Mala. Celular. Dinheiro R$ 2404,00 | L19: 16 tijolos. 7816 g | M19: 0 | N19: 0 | O19: 0 | P19: 0 | Q19: 0 | R19: Art. 33. Art. 35 | S19: Não | T19: Preso no momento da sentença. Denúncia | U19: Procedente | V19: Art. 33. Art. 35 | W19: NA | X19: Não | Y19: 5a | Z19: Não | AA19: Não | AB19: Não | AC19: Não | AD19: 5a | AE19: 3a | AF19: NA | AG19: 8a | AH19: NA | AI19: Fechado
A20: 0055873-39.2017.8.26.0050 | B20: 43069 | C20: Carlos José Zulian | D20: 1ª Vara Criminal | E20: ANDERSON RICARDO DE PAULA | F20: Via Pública | G20: Masculino | H20: 34118 | I20: Preta | J20: Não disponível | K20: Embalagens. Balança. Fermento em pó. Celular. Faca. Colher. Bacia. Liquidificador | L20: 1 tijolo. 189,5 g. 50 porções. 81,8 g | M20: 357 porções. 211,5 g | N20: 0 | O20: 0 | P20: 0 | Q20: 0 | R20: Art. 33 | S20: Não | T20: Preso no momento da sentença. Denúncia anônima | U20: Procedente | V20: Art. 33 | W20: NA | X20: Não | Y20: 5a | Z20: Não | AA20: Não | AB20: Não | AC20: Sim parcial | AD20: 3a | AE20: NA | AF20: NA | AG20: 3a | AH20: Sim | AI20: NA
A21: 0096963-61.2016.8.26.0050 | B21: 42958 | C21: Carlos José Zulian | D21: 1ª Vara Criminal | E21: GABRIEL SANCHEZ ORLANDO | F21: Via Pública | G21: Masculino | H21: 33993 | I21: Branca | J21: Liso | K21: Veículo. Balança. Celular. Dinheiro R$ 212,00 | L21: 1 tijolo. 488,4 g. 2 pés. 149,9 g | M21: 0 | N21: 0 | O21: 0 | P21: 0 | Q21: 0 | R21: Art. 33 | S21: Não | T21: Confissão informal. Denúncia | U21: Parcialmente procedente | V21: Art. 33 | W21: NA | X21: Não | Y21: 5a | Z21: Não | AA21: Não | AB21: Não | AC21: Não | AD21: 5a | AE21: NA | AF21: NA | AG21: 5a | AH21: NA | AI21: Fechado
A22: 0096963-61.2016.8.26.0050 | B22: 42958 | C22: Carlos José Zulian | D22: 1ª Vara Criminal | E22: Fernando Rodrigues Sevilhano | F22: Via Pública | G22: Masculino | H22: 34396 | I22: Branca | J22: Liso | K22: Dinheiro R$ 60,00 | L22: 1 tijolo. 2 vidros. 2372,2 g (total) | M22: 0 | N22: 0 | O22: 0 | P22: 0 | Q22: 0 | R22: Art. 33 | S22: Não | T22: Não há | U22: Procedente | V22: Art. 33 | W22: NA | X22: Não | Y22: 5a | Z22: Não | AA22: Não | AB22: Não | AC22: Não | AD22: 5a | AE22: NA | AF22: NA | AG22: 5a | AH22: NA | AI22: Fechado
A23: 0013747-96.2016.8.26.0635 | B23: 42930 | C23: Carlos José Zulian | D23: 1ª Vara Criminal | E23: SILVANIL CAMPANHA VIEIRA | F23: Via Pública | G23: Masculino | H23: 32988 | I23: Parda | J23: Carapinha | K23: Cachimbo. R$ 10,00 | L23: 0 | M23: 0 | N23: 1 porção. 0,2 g | O23: 0 | P23: 0 | Q23: 0 | R23: Art. 33 | S23: Não | T23: Preso no momento da sentença. Local de tráfico | U23: Procedente | V23: Art. 33 | W23: NA | X23: Sim. Antecedentes | Y23: 5a 10m | Z23: Reincidência | AA23: Não | AB23: Não | AC23: Não cabimento | AD23: 6a 9m 20d | AE23: NA | AF23: NA | AG23: 6a 9m 20d | AH23: NA | AI23: Fechado
A24: 0004370-76.2017.8.26.0050 | B24: 42934 | C24: Carlos José Zulian | D24: 1ª Vara Criminal | E24: OMIR TOME NETO | F24: Via Pública | G24: Masculino | H24: 34292 | I24: Branca | J24: Ondulado | K24: Dinheiro R$ 5,00 | L24: 20 porções. 17,6 g | M24: 21 porções. 15,2 g | N24: 3 porções. 3,7 g | O24: 0 | P24: 0 | Q24: 0 | R24: Art. 33 | S24: Não | T24: Preso no momento da sentença | U24: Absolvição | V24: NA | W24: NA | X24: NA | Y24: NA | Z24: NA | AA24: NA | AB24: NA | AC24: NA | AD24: NA | AE24: NA | AF24: NA | AG24: NA | AH24: NA | AI24: NA
A25: 0004434-23.2016.8.26.0050 | B25: 42765 | C25: Carlos José Zulian | D25: 1ª Vara Criminal | E25: JAILSON ANDRE DA SILVA | F25: Via Pública | G25: Masculino | H25: 32782 | I25: Parda | J25: Encaracolado | K25: Pochete. Papéis. Dinheiro R$ 60,00 | L25: 61 porções. 67 g | M25: 54 porções. 10 g | N25: 81 porções. 17 g | O25: 0 | P25: 0 | Q25: 0 | R25: Art. 33 | S25: Não | T25: Local de tráfico. Preso no momento da sentença | U25: Procedente | V25: Art. 33 | W25: NA | X25: Sim. Antecedentes | Y25: 5a 10m | Z25: Reincidência | AA25: Não | AB25: Não | AC25: Não cabimento | AD25: 6a 9m 20d | AE25: NA | AF25: NA | AG25: 6a 9m 20d | AH25: NA | AI25: Fechado
A26: 0012132-71.2016.8.26.0635 | B26: 43069 | C26: Carlos José Zulian | D26: 1ª Vara Criminal | E26: CAUE LEANDRO DA SILVA CEGARRA LYRA | F26: Via Pública | G26: Masculino | H26: 35694 | I26: Branca | J26: Não disponível | K26: Veículo. Dinheiro R$ 641,80 | L26: 2072,3 g | M26: 59,8 g | N26: 0 | O26: 0 | P26: 0 | Q26: 0 | R26: Art. 33 | S26: Não | T26: Preso no momento da sentença. Local de tráfico | U26: Procedente | V26: Art. 33 | W26: NA | X26: Não | Y26: 5a | Z26: Não | AA26: Não | AB26: Não | AC26: Não | AD26: 5a | AE26: NA | AF26: NA | AG26: 5a | AH26: NA | AI26: Fechado
A27: 0030299-48.2016.8.26.0050 | B27: 42807 | C27: Carlos José Zulian | D27: 1ª Vara Criminal | E27: ANUNCIATO MARCELINO DE OLIVEIRA NETO | F27: Via Pública | G27: Masculino | H27: 30612 | I27: Branca | J27: Encaracolado | K27: Veículo. Celular | L27: 0 | M27: 1 tijolo. 931,2 g | N27: 0 | O27: 0 | P27: 0 | Q27: 0 | R27: Art. 33. Art. 35 | S27: Não | T27: Preso no momento da sentença | U27: Absolvição | V27: NA | W27: NA | X27: NA | Y27: NA | Z27: NA | AA27: NA | AB27: NA | AC27: NA | AD27: NA | AE27: NA | AF27: NA | AG27: NA | AH27: NA | AI27: NA
A28: 00118686320168260050 | B28: 03/05/2017 | C28: Maria Cecília Leone | D28: 10ª Vara Criminal | E28: BRUNO DE OLIVEIRA CALACA | F28: Área não ocupada | G28: Masculino | H28: 34329 | I28: Parda | J28: Carapinha | K28: Celular. Dinheiro R$ 64,00 | L28: 13 porções. 18 g | M28: 16 porções. 1,1 g | N28: 0 | O28: 0 | P28: 0 | Q28: 0 | R28: Art. 33 | S28: Não | T28: Local de tráfico. Confissão informal | U28: Procedente | V28: Art. 33 | W28: NA | X28: Não | Y28: 5a | Z28: Não | AA28: Não | AB28: Não | AC28: Não | AD28: 5a | AE28: NA | AF28: NA | AG28: 5a | AH28: NA | AI28: Fechado
A29: 00097232520168260635 | B29: 27/04/2017 | C29: Maria Cecília Leone | D29: 10ª Vara Criminal | E29: GUSTAVO IAN DOS SANTOS | F29: Via Pública | G29: Masculino | H29: 35234 | I29: Parda | J29: Não disponível | K29: Colher. Peneira. Tubo. Invólucro. Papel filme | L29: 0 | M29: 7 porções. 16,8 g | N29: 53 porções. 18,6 g | O29: 0 | P29: 0 | Q29: 0 | R29: Art. 33 | S29: Não | T29: Confissão informal. Confissão. Preso no momento da sentença. Atitude suspeita | U29: Procedente | V29: Art. 33 | W29: NA | X29: Não | Y29: 5a | Z29: Não | AA29: Não | AB29: Não | AC29: Sim parcial | AD29: 2a 6m | AE29: NA | AF29: NA | AG29: 2a 6m | AH29: Não | AI29: Fechado
A30: 00132837220168260635 | B30: 17/07/2017 | C30: Marcelo Matias Pereira | D30: 10ª Vara Criminal | E30: ALBERTO DIEGO DOS REMEDIOS | F30: Via Pública | G30: Masculino | H30: 32339 | I30: Parda | J30: Liso | K30: Bolsa. Chave. Papel filme. Papel alumínio. Dinheiro R$ 102,00 | L30: 10 tijolos. 9903 g | M30: 0 | N30: 0 | O30: 0 | P30: 0 | Q30: 0 | R30: Art. 33 | S30: Não | T30: Confissão. Preso no momento da sentença | U30: Procedente | V30: Art. 33 | W30: NA | X30: Sim. Quantidade | Y30: 7a 6m | Z30: Reincidência | AA30: Confissão | AB30: Não | AC30: Não | AD30: 7a 6m | AE30: NA | AF30: NA | AG30: 7a 6m | AH30: NA | AI30: Fechado
A31: 00132837220168260635 | B31: 17/07/2017 | C31: Marcelo Matias Pereira | D31: 10ª Vara Criminal | E31: JAIRO ALVES DA SILVA | F31: Via Pública | G31: Masculino | H31: 31328 | I31: Parda | J31: Ondulado | K31: Bolsa. Chave. Papel filme. Papel alumínio. Dinheiro R$ 102,00 | L31: 10 tijolos. 9903 g | M31: 0 | N31: 0 | O31: 0 | P31: 0 | Q31: 0 | R31: Art. 33 | S31: Não | T31: Preso no momento da sentença | U31: Procedente | V31: Art. 33 | W31: NA | X31: Sim. Quantidade | Y31: 7a 6m | Z31: Não | AA31: Não | AB31: Não | AC31: Não | AD31: 7a 6m | AE31: NA | AF31: NA | AG31: 7a 6m | AH31: NA | AI31: Fechado
A32: 00473220720168260050 | B32: 09/05/2017 | C32: Daiane Saladini Monari | D32: 10ª Vara Criminal | E32: ISRAEL VIEIRA DOS SANTOS | F32: Residência | G32: Masculino | H32: 30801 | I32: Parda | J32: Não disponível | K32: Pochete. Dinheiro R$ 45,00 | L32: 41 porções. 66,3 g | M32: 18 porções. 17,8 g | N32: 54 porções. 11,7 g | O32: 0 | P32: 0 | Q32: 0 | R32: Art. 33 | S32: Não | T32: Confissão. Local de tráfico. Preso no momento da sentença | U32: Procedente | V32: Art. 33 | W32: NA | X32: Sim. Natureza | Y32: 5a 10m | Z32: Não | AA32: Confissão | AB32: Não | AC32: Não | AD32: 5a | AE32: NA | AF32: NA | AG32: 5a | AH32: NA | AI32: Fechado
A33: 00110475020168260635 | B33: 11/07/2017 | C33: Marcelo Matias Pereira | D33: 10ª Vara Criminal | E33: CRISTIANO DE JESUS SANTOS | F33: Via Pública | G33: Masculino | H33: 31129 | I33: Parda | J33: Carapinha | K33: Celular. Dinheiro R$ 92,00 | L33: 14 porções. 7 g | M33: 0 | N33: 44 porções. 15,8 g | O33: 0 | P33: 0 | Q33: 0 | R33: Art. 33 | S33: Não | T33: Confissão informal. Preso no momento da sentença | U33: Procedente | V33: Art. 33 | W33: NA | X33: Não | Y33: 5a | Z33: Não | AA33: Não | AB33: Não | AC33: Não | AD33: 5a | AE33: NA | AF33: NA | AG33: 5a | AH33: NA | AI33: Fechado
A34: 00182053420178260050 | B34: 09/08/2017 | C34: Maria Cecília Leone | D34: 10ª Vara Criminal | E34: IGOR LOPES FONTES SILVA | F34: Via Pública | G34: Masculino | H34: 35499 | I34: Branca | J34: Carapinha | K34: Mochila. Celular | L34: 190 porções. 1832,5 g | M34: 1003 porções. 187,2 g | N34: 0 | O34: 0 | P34: 0 | Q34: Lança-perfume. 40 frascos. 160 ml | R34: Art. 33 | S34: Não | T34: Confissão. Preso no momento da sentença | U34: Procedente | V34: Art. 33 | W34: NA | X34: Não | Y34: 5a | Z34: Não | AA34: Não | AB34: Não | AC34: Não | AD34: 5a | AE34: NA | AF34: NA | AG34: 5a | AH34: NA | AI34: Fechado
A35: 00058525020178260635 | B35: 24/10/2017 | C35: Marcelo Matias Pereira | D35: 10ª Vara Criminal | E35: GISELE APARECIDA RIBEIRO | F35: Via Pública | G35: Feminino | H35: 35584 | I35: Parda | J35: Não disponível | K35: Bilhete único. Celular. Dinheiro R$ 62,00 | L35: 14 porções. 20,8 g | M35: 27 porções. 20,6 g | N35: 0 | O35: 0 | P35: 0 | Q35: 0 | R35: Art. 33 | S35: Não | T35: Local de tráfico. Presa no momento da sentença | U35: Procedente | V35: Art. 33 | W35: NA | X35: Não | Y35: 5a | Z35: Não | AA35: Não | AB35: Adolescente | AC35: Sim parcial | AD35: 2a 11m | AE35: NA | AF35: NA | AG35: 2a 11m | AH35: Não | AI35: Fechado
A36: 00005711620178260635 | B36: 31/08/2017 | C36: Marcelo Matias Pereira | D36: 10ª Vara Criminal | E36: RONALDO AMARANTE DA SILVA | F36: Via Pública | G36: Masculino | H36: 29927 | I36: Parda | J36: Não disponível | K36: Papel. Rádio transmissor. Dinheiro R$ 34,00 | L36: 0 | M36: 55 porções. 26,5 g | N36: 0 | O36: 0 | P36: 0 | Q36: 0 | R36: Art. 33 | S36: Não | T36: Preso no momento da sentença | U36: Procedente | V36: Art. 33 | W36: NA | X36: Não | Y36: 5a | Z36: Reincidência | AA36: Não | AB36: Não | AC36: Não cabimento | AD36: 5a 10m | AE36: NA | AF36: NA | AG36: 5a 10m | AH36: NA | AI36: Fechado
A37: 01019426620168260050 | B37: 14/07/2017 | C37: Maria Cecília Leone | D37: 10ª Vara Criminal | E37: THAIS DOS SANTOS MIRANDA | F37: Via Pública | G37: Feminino | H37: 35336 | I37: Parda | J37: Não disponível | K37: Dinheiro R$ 262,00 | L37: 0 | M37: 36 porções. 28,9 g | N37: 0 | O37: 0 | P37: 0 | Q37: 0 | R37: Art. 33 | S37: Não | T37: Confissão | U37: Procedente | V37: Art. 33 | W37: NA | X37: Não | Y37: 5a | Z37: Não | AA37: Não | AB37: Adolescente | AC37: Sim parcial | AD37: 2a 11m | AE37: NA | AF37: NA | AG37: 2a 11m | AH37: Sim | AI37: NA
A38: 01059208520158260050 | B38: 13/01/2017 | C38: Maria Cecília Leone | D38: 10ª Vara Criminal | E38: WAGNER ROBERTO SOARES | F38: Via Pública | G38: Masculino | H38: 29819 | I38: Parda | J38: Carapinha | K38: Pochete. Dinheiro R$ 54,00 | L38: 0 | M38: 21 porções. 7,2 g | N38: 100 porções. 21,1 g | O38: 0 | P38: 0 | Q38: 0 | R38: Art. 33 | S38: Não | T38: Local de tráfico. Confissão informal. Preso no momento da sentença | U38: Procedente | V38: Art. 33 | W38: NA | X38: Sim. Antecedentes. Variedade | Y38: 5a 10m | Z38: Reincidência | AA38: Não | AB38: Não | AC38: Não cabimento | AD38: 6a 9m 20d | AE38: NA | AF38: NA | AG38: 6a 9m 20d | AH38: NA | AI38: Fechado
A39: 00085284820158260050 | B39: 03/05/2017 | C39: Marcos Fleury Silveira de Alvarenga | D39: 12ª Vara Criminal | E39: XIUYU HUANG | F39: Comércio e serviços | G39: Feminino | H39: Não disponível | I39: Amarela | J39: Liso | K39: Mochila. Dinheiro R$ 17369,00 | L39: 1 porção. 69,7 g | M39: 4 porções. 18,7 g | N39: 0 | O39: 0 | P39: 0 | Q39: 0 | R39: Art. 33 | S39: Não | T39: Nacionalidade | U39: Absolvição | V39: NA | W39: NA | X39: NA | Y39: NA | Z39: NA | AA39: NA | AB39: NA | AC39: NA | AD39: NA | AE39: NA | AF39: NA | AG39: NA | AH39: NA | AI39: NA
A40: 00934274220168260050 | B40: 12/07/2017 | C40: Marcos Fleury Silveira de Alvarenga | D40: 12ª Vara Criminal | E40: GUILHERME HENRIQUE DA SILVA ROCHA | F40: Via Pública | G40: Masculino | H40: 33304 | I40: Parda | J40: Não disponível | K40: Celular. Dinheiro R$ 172,00 | L40: 29 porções. 51,4 g | M40: 28 porções. 22 g | N40: 0 | O40: 0 | P40: 0 | Q40: 0 | R40: Art. 33 | S40: Não | T40: Confissão. Preso no momento da sentença. Atitude suspeita | U40: Procedente | V40: Art. 33 | W40: NA | X40: Não | Y40: 5a | Z40: Não | AA40: Não | AB40: Não | AC40: Sim total | AD40: 1a 8m | AE40: NA | AF40: NA | AG40: 1a 8m | AH40: Não | AI40: Aberto
...

Sheet TJSP - Apenas p Complementação
A1: NUM_PROCESSO | B1: NME_FORO | C1: NME_VARA | D1: NME_REU | E1: IDADE_REU | F1: TPO_GENERO | G1: DSC_COR
A2: 00003703320178260050 | B2: Foro Central Criminal Barra Funda | C2: 1ª Vara Criminal | D2: PATRICK DE CAMPOS SAPRAGONES CANO | E2: 18 | F2: M | G2: Pardo
A3: 00006579320178260050 | B3: Foro Central Criminal Barra Funda | C3: 1ª Vara Criminal | D3: ALEXANDRE RODRIGUES | E3: 0 | F3: M | G3: Branco
A4: 00007825220178260635 | B4: Foro Central Criminal Barra Funda | C4: 1ª Vara Criminal | D4: ADRIANO ROGERIO RIBEIRO | E4: 19 | F4: M | G4: Preto
A5: 00009201920178260635 | B5: Foro Central Criminal Barra Funda | C5: 1ª Vara Criminal | D5: DILEIA OLIVEIRA DA SILVA | E5: 35 | F5: F | G5: Pardo
A6: 00009201920178260635 | B6: Foro Central Criminal Barra Funda | C6: 1ª Vara Criminal | D6: LUIZ FELIPE DE MIRANDA SANTOS | E6: 23 | F6: M | G6: Pardo
A7: 00011299420178260050 | B7: Foro Central Criminal Barra Funda | C7: 1ª Vara Criminal | D7: FERNANDO RIBEIRO CREMASCO | E7: 42 | F7: M | G7: Branco
A8: 00011299420178260050 | B8: Foro Central Criminal Barra Funda | C8: 1ª Vara Criminal | D8: JURANDIR JEREMIAS | E8: 41 | F8: M | G8: Pardo
A9: 00011470920178260635 | B9: Foro Central Criminal Barra Funda | C9: 1ª Vara Criminal | D9: MAURICIO DA SILVA MORAIS (Matrícula SAP 354340-2) | E9: 31 | F9: M | G9: Pardo
A10: 00011470920178260635 | B10: Foro Central Criminal Barra Funda | C10: 1ª Vara Criminal | D10: ROBSON LUIZ DOS SANTOS | E10: 26 | F10: M | G10: Pardo
A11: 00011647920168260635 | B11: Foro Central Criminal Barra Funda | C11: 1ª Vara Criminal | D11: VAGNER FELIX DO NASCIMENTO | E11: 24 | F11: M | G11: NULL
A12: 00011647920168260635 | B12: Foro Central Criminal Barra Funda | C12: 1ª Vara Criminal | D12: KAIQUE HUMBERTO DA SILVA | E12: 20 | F12: M | G12: NULL
A13: 00012632420178260050 | B13: Foro Central Criminal Barra Funda | C13: 1ª Vara Criminal | D13: JOSE BEZERRA DA SILVA | E13: 31 | F13: M | G13: Pardo
... A63: 00315544120168260050 | B63: Foro Central Criminal Barra Funda | C63: 1ª Vara Criminal | D63: klaus dos santos souza | E63: 29 | F63: M | G63: NULL
A64: 00330614720108260050 | B64: Foro Central Criminal Barra Funda | C64: 1ª Vara Criminal | D64: SONIA APARECIDA ROSSI | E64: NULL | F64: F | G64: NULL
A65: 00330614720108260050 | B65: Foro Central Criminal Barra Funda | C65: 1ª Vara Criminal | D65: Sidney da Silva Moreira | E65: NULL | F65: M | G65: Branco
A66: 00330614720108260050 | B66: Foro Central Criminal Barra Funda | C66: 1ª Vara Criminal | D66: RENATO ALEXANDRE JUNIOR | E66: NULL | F66: M | G66: NULL
A67: 00330614720108260050 | B67: Foro Central Criminal Barra Funda | C67: 1ª Vara Criminal | D67: VANDO FRANCISCO SCALEZE | E67: 34 | F67: M | G67: NULL
A68: 00330614720108260050 | B68: Foro Central Criminal Barra Funda | C68: 1ª Vara Criminal | D68: EDNEY FERREIRA MARQUES | E68: 30 | F68: M | G68: NULL
A69: 00330614720108260050 | B69: Foro Central Criminal Barra Funda | C69: 1ª Vara Criminal | D69: FERNANDO OLIVEIRA DAS NEVES | E69: 33 | F69: M | G69: Pardo
A70: 00330614720108260050 | B70: Foro Central Criminal Barra Funda | C70: 1ª Vara Criminal | D70: RODRIGO UBIRAJARA DE GOUVEA | E70: NULL | F70: M | G70: NULL
A71: 00330614720108260050 | B71: Foro Central Criminal Barra Funda | C71: 1ª Vara Criminal | D71: CLEBER PILLA DOS SANTOS | E71: NULL | F71: M | G71: NULL
A72: 00330614720108260050 | B72: Foro Central Criminal Barra Funda | C72: 1ª Vara Criminal | D72: RAFAEL CHAVES FRIAS | E72: 28 | F72: M | G72: NULL
A73: 00382047020178260050 | B73: Foro Central Criminal Barra Funda | C73: 1ª Vara Criminal | D73: CICERO DOS SANTOS SILVA | E73: 20 | F73: M | G73: Pardo
A74: 00385660920168260050 | B74: Foro Central Criminal Barra Funda | C74: 1ª Vara Criminal | D74: MARCOS PEDROSO DOS SANTOS | E74: 27 | F74: M | G74: Branco
A75: 00403765820128260050 | B75: Foro Central Criminal Barra Funda | C75: 1ª Vara Criminal | D75: JAILTON DOS SANTOS SOARES | E75: 32 | F75: M | G75: Pardo
A76: 00405254920158260050 | B76: Foro Central Criminal Barra Funda | C76: 1ª Vara Criminal | D76: TIAGO FERREIRA ALVES | E76: 26 | F76: M | G76: Pardo
A77: 00427942720168260050 | B77: Foro Central Criminal Barra Funda | C77: 1ª Vara Criminal | D77: anderson carlos gomes da silva | E77: 21 | F77: M | G77: NULL
A78: 00427942720168260050 | B78: Foro Central Criminal Barra Funda | C78: 1ª Vara Criminal | D78: rodrigo cordeiro da silva | E78: 34 | F78: M | G78: NULL
A79: 00433092820178260050 | B79: Foro Central Criminal Barra Funda | C79: 1ª Vara Criminal | D79: LUCIANO JOSE DA SILVA SANTOS | E79: 38 | F79: M | G79: Branco
A80: 00455414720168260050 | B80: Foro Central Criminal Barra Funda | C80: 1ª Vara Criminal | D80: CIRO DA ROCHA NUNES DOS SANTOS | E80: 25 | F80: M | G80: Branco
A81: 00460013420168260050 | B81: Foro Central Criminal Barra Funda | C81: 1ª Vara Criminal | D81: DONVANE SANTOS RIBEIRO | E81: 22 | F81: M | G81: Pardo
A82: 00471633020178260050 | B82: Foro Central Criminal Barra Funda | C82: 1ª Vara Criminal | D82: LEONARDO CARDOSO VIEIRA | E82: 31 | F82: M | G82: Branco
A83: 00471633020178260050 | B83: Foro Central Criminal Barra Funda | C83: 1ª Vara Criminal | D83: TATIANE BECKER DOS SANTOS | E83: 21 | F83: F | G83: Branco
... A202: 00522061620158260050 | B202: Foro Central Criminal Barra Funda | C202: 10ª Vara Criminal | D202: MARCOS ANTONIO GONCALVES DOS SANTOS | E202: 18 | F202: M | G202: Pardo
A203: 00532926120118260050 | B203: Foro Central Criminal Barra Funda | C203: 10ª Vara Criminal | D203: ANDRE RICARDO CARDOSO SANTANA | E203: NULL | F203: M | G203: NULL
A204: 00534374420168260050 | B204: Foro Central Criminal Barra Funda | C204: 10ª Vara Criminal | D204: ARNALDO ALVES CARDOSO | E204: 54 | F204: M | G204: Preto
A205: 00539637920148260050 | B205: Foro Central Criminal Barra Funda | C205: 10ª Vara Criminal | D205: Jefferson Ribeiro da Silva | E205: 25 | F205: M | G205: Branco
A206: 00550596120168260050 | B206: Foro Central Criminal Barra Funda | C206: 10ª Vara Criminal | D206: BRUNO APARECIDO MORAIS DE SA | E206: 22 | F206: M | G206: Branco
A207: 00557204020168260050 | B207: Foro Central Criminal Barra Funda | C207: 10ª Vara Criminal | D207: ERIK BATISTA FARIA | E207: 33 | F207: M | G207: Pardo
...

Sheet BD
A1: ID | B1: Processo | C1: Processo (cont) | D1: DtDisp | E1: Juiz | F1: Sexo Juiz | G1: Vara | H1: Nome | I1: Nome (cont) | J1: Local | K1: Sexo | L1: DN | M1: Idade | N1: Cutis | O1: Cutis (agrup) | P1: Cabelo | Q1: Objetos | R1: Maconha | S1: Maconha (g) | T1: Cocaína | U1: Cocaína (g) | V1: Crack | W1: Crack (g) | X1: Ecstasy | Y1: Ecstasy (g) | Z1: LSD | AA1: LSD (g) | AB1: Outras | AC1: Anabolizantes | AD1: Anorexígenos | AE1: Haxixe | AF1: Skank | AG1: Lança-perfume | AH1: Tolueno | AI1: DenDrog | AJ1: DenOutros | AK1: Aspectos | AL1: Sentença | AM1: Sentença (agrup) | AN1: ResDrogas | AO1: ResOutros | AP1: AvalNegPB | AQ1: PenaBase | AR1: Agravantes33 | AS1: Agravantes33 (agrup) | AT1: Atenuantes33 | AU1: Confissão | AV1: Menoridade | AW1: Nenhum | AX1: NA | AY1: Atenuantes33 (agrup) | AZ1: Aumento33 | BA1: Adolescente | BB1: Arma de fogo | BC1: Interestadual | BD1: Conc. Form. | BE1: Estabelecimento | BF1: Nenhum | BG1: NA | BH1: Aumento33 (agrup) | BI1: §4º | BJ1: §4º (agrupado) | BK1: Pena33 | BL1: Pena33 (meses) | BM1: PenaDrogas | BN1: PenaOutros | BO1: TotPen | BP1: TotPen (meses) | BQ1: Substituição da pena | BR1: Regime inicial | BS1: Regime inicial (agrupado)
A2: 1 | B2: 00316684320178260050 | C2: 1 | D2: 08/06/2017 | E2: Carlos Eduardo Lora Franco | F2: Masculino | G2: 3ª Vara Criminal | H2: Milton Teixeira da Silva | I2: 1 | J2: Comércio e serviços | K2: Masculino | L2: 27624 | M2: 41 | N2: Preta | O2: Negros, pardos e outros | P2: Carapinha | Q2: Bolsa | R2: 0 | S2: 0 | T2: 3 pacotes. 1971,3 g | U2: 1971.3 | V2: 0 | W2: 0 | X2: 0 | Y2: 0 | Z2: 0 | AA2: 0 | AB2: 0 | AC2: Não | AD2: Não | AE2: Não | AF2: Não | AG2: Não | AH2: Não | AI2: Art. 33 | AJ2: Não | AK2: Preso no momento da sentença | AL2: Procedente | AM2: Condenação por tráfico | AN2: Art. 33 | AO2: NA | AP2: Sim. Antecedentes. Natureza. Quantidade | AQ2: 8a | AR2: Reincidência | AS2: Sim | AT2: Não | AU2: Não | AV2: Não | AW2: Sim | AX2: Não | AY2: Não | AZ2: Não | BA2: Não | BB2: Não | BC2: Não | BD2: Não | BE2: Não | BF2: =IF(AZ2="Não","Sim","Não") -> Sim | BG2: =IF(AZ2="NA","Sim","Não") -> Não | BH2: Não | BI2: Não cabimento | BJ2: Não cabimento / Não informado | BK2: 10a | BL2: 120 | BM2: NA | BN2: NA | BO2: 10a | BP2: 120 | BQ2: NA | BR2: Fechado | BS2: NA (Pena Total > 8)
A3: 2 | B3: 00126324020168260635 | C3: 0 | D3: 17/03/2017 | E3: Carlos Eduardo Lora Franco | F3: Masculino | G3: 3ª Vara Criminal | H3: Gabriel Pereira Araújo | I3: 1 | J3: Via Pública | K3: Masculino | L3: 34466 | M3: 22 | N3: Preta | O3: Negros, pardos e outros | P3: Não disponível | Q3: Nada | R3: 80 porções. 148,5 g | S3: 148.5 | T3: 57 porções. 36,6 g | U3: 36.6 | V3: 7 porções. 1,1 g | W3: 1.1 | X3: 0 | Y3: 0 | Z3: 0 | AA3: 0 | AB3: Haxixe. 37 porções. 9,9 g. Skank. 1 porção. 0,9 g | AC3: Não | AD3: Não | AE3: Sim | AF3: Sim | AG3: Não | AH3: Não | AI3: Art. 33. Art. 35 | AJ3: Art. 244-B ECA | AK3: Local de tráfico. Preso no momento da sentença | AL3: Parcialmente procedente | AM3: Condenação por tráfico | AN3: Art. 33 | AO3: Não | AP3: Sim. Natureza. Quantidade. Variedade | AQ3: 7a | AR3: Reincidência | AS3: Sim | AT3: Não | AU3: Não | AV3: Não | AW3: Sim | AX3: Não | AY3: Não | AZ3: Adolescente | BA3: Sim | BB3: Não | BC3: Não | BD3: Não | BE3: Não | BF3: =IF(AZ3="Não","Sim","Não") -> Não | BG3: =IF(AZ3="NA","Sim","Não") -> Não | BH3: Sim | BI3: Não cabimento | BJ3: Não cabimento / Não informado | BK3: 10a 2m 15d | BL3: 122.5 | BM3: NA | BN3: NA | BO3: 10a 2m 15d | BP3: 122.5 | BQ3: NA | BR3: Fechado | BS3: NA (Pena Total > 8)
A4: 3 | B4: 00818385320168260050 | C4: 1 | D4: 24/01/2017 | E4: Adriana Costa | F4: Feminino | G4: 21ª Vara Criminal | H4: JORGE ELIEL PEREIRA DE CASTRO | I4: 1 | J4: Via Pública | K4: Masculino | L4: 33108 | M4: 26 | N4: Parda | O4: Negros, pardos e outros | P4: Não disponível | Q4: Estojo. Dinheiro R$ 20,00 | R4: 35 porções. 56 g | S4: 56 | T4: 43 porções. 15,5 g | U4: 15.5 | V4: 95 porções. 22,6 g | W4: 22.6 | X4: 0 | Y4: 0 | Z4: 0 | AA4: 0 | AB4: 0 | AC4: Não | AD4: Não | AE4: Não | AF4: Não | AG4: Não | AH4: Não | AI4: Art. 33 | AJ4: Art. 244-B ECA | AK4: Preso no momento da sentença. Denúncia | AL4: Parcialmente procedente | AM4: Condenação por tráfico | AN4: Art. 33 | AO4: Não | AP4: Sim. Conduta. Quantidade | AQ4: 6a | AR4: Reincidência | AS4: Sim | AT4: Não | AU4: Não | AV4: Não | AW4: Sim | AX4: Não | AY4: Não | AZ4: Adolescente | BA4: Sim | BB4: Não | BC4: Não | BD4: Não | BE4: Não | BF4: =IF(AZ4="Não","Sim","Não") -> Não | BG4: =IF(AZ4="NA","Sim","Não") -> Não | BH4: Sim | BI4: Não cabimento | BJ4: Não cabimento / Não informado | BK4: 10a 6m | BL4: 126 | BM4: NA | BN4: NA | BO4: 10a 6m | BP4: 126 | BQ4: NA | BR4: Fechado | BS4: NA (Pena Total > 8)
A5: 4 | B5: 00973992020168260050 | C5: 1 | D5: 19/05/2017 | E5: Tamara Priscila Tocci | F5: Feminino | G5: 29ª Vara Criminal | H5: RODOLFO FEITOSA DE PAULA | I5: 1 | J5: Residência | K5: Masculino | L5: 30213 | M5: 34 | N5: Parda | O5: Negros, pardos e outros | P5: Não disponível | Q5: Sacola. Caderno | R5: 1639 porções. 2530 g | S5: 2530 | T5: 1816 porções. 1980 g | U5: 1980 | V5: 3700 porções. 858 g | W5: 858 | X5: 0 | Y5: 0 | Z5: 0 | AA5: 0 | AB5: 0 | AC5: Não | AD5: Não | AE5: Não | AF5: Não | AG5: Não | AH5: Não | AI5: Art. 33 | AJ5: Não | AK5: Confissão informal. Preso no momento da sentença. Investigação | AL5: Procedente | AM5: Condenação por tráfico | AN5: Art. 33 | AO5: NA | AP5: Sim. Antecedentes. Natureza. Quantidade. Variedade | AQ5: 9a 8m 20d | AR5: Reincidência | AS5: Sim | AT5: Não | AU5: Não | AV5: Não | AW5: Sim | AX5: Não | AY5: Não | AZ5: Não | BA5: Não | BB5: Não | BC5: Não | BD5: Não | BE5: Não | BF5: =IF(AZ5="Não","Sim","Não") -> Sim | BG5: =IF(AZ5="NA","Sim","Não") -> Não | BH5: Não | BI5: Não cabimento | BJ5: Não cabimento / Não informado | BK5: 10a 9m 19d | BL5: 129.63333 | BM5: NA | BN5: NA | BO5: 10a 9m 19d | BP5: 129.63333 | BQ5: NA | BR5: Fechado | BS5: NA (Pena Total > 8)
A6: 5 | B6: 00055277520178260635 | C6: 1 | D6: 12/09/2017 | E6: José Roberto Cabral Longaretti | F6: Masculino | G6: 13ª Vara Criminal | H6: CLAUDIO WASHINGTON MENDES DA SILVA | I6: 1 | J6: Residência | K6: Masculino | L6: 33769 | M6: 25 | N6: Preta | O6: Negros, pardos e outros | P6: Outros | Q6: Celular. Dinheiro R$ 15000,00 | R6: 0 | S6: 0 | T6: 0 | U6: 0 | V6: 65 pacotes. 3334,6 g | W6: 3334.6 | X6: 0 | Y6: 0 | Z6: 0 | AA6: 0 | AB6: 0 | AC6: Não | AD6: Não | AE6: Não | AF6: Não | AG6: Não | AH6: Não | AI6: Art. 33 | AJ6: Art. 333 CP | AK6: Confissão informal. Preso no momento da sentença | AL6: Parcialmente procedente | AM6: Condenação por tráfico | AN6: Art. 33 | AO6: Não | AP6: Sim. Quantidade | AQ6: 8a | AR6: Reincidência | AS6: Sim | AT6: Não | AU6: Não | AV6: Não | AW6: Sim | AX6: Não | AY6: Não | AZ6: Adolescente. Arma de fogo | BA6: Sim | BB6: Sim | BC6: Não | BD6: Não | BE6: Não | BF6: =IF(AZ6="Não","Sim","Não") -> Não | BG6: =IF(AZ6="NA","Sim","Não") -> Não | BH6: Sim | BI6: Não cabimento | BJ6: Não cabimento / Não informado | BK6: 11a 2m 12d | BL6: 134.4 | BM6: NA | BN6: NA | BO6: 11a 2m 12d | BP6: 134.4 | BQ6: NA | BR6: Fechado | BS6: NA (Pena Total > 8)
A7: 6 | B7: 00269673920178260050 | C7: 1 | D7: 11/07/2017 | E7: Rafael Henrique Janela Tamai Rocha | F7: Masculino | G7: 22ª Vara Criminal | H7: LUIZ CARLOS FELIX DE SOUZA | I7: 1 | J7: Residência | K7: Masculino | L7: 26835 | M7: 44 | N7: Parda | O7: Negros, pardos e outros | P7: Carapinha | Q7: Veículo. Balança. Papéis | R7: 1 tijolo. 515,68 g | S7: 515.68 | T7: 8 porções. 11 g | U7: 11 | V7: 42 porções. 8,5 g | W7: 8.5 | X7: 0 | Y7: 0 | Z7: 0 | AA7: 0 | AB7: 0 | AC7: Não | AD7: Não | AE7: Não | AF7: Não | AG7: Não | AH7: Não | AI7: Art. 33. Art. 35 | AJ7: Não | AK7: Investigação. Preso no momento da sentença | AL7: Parcialmente procedente | AM7: Condenação por tráfico | AN7: Art. 33 | AO7: NA | AP7: Sim. Antecedentes. Natureza. Quantidade | AQ7: 10a | AR7: Reincidência | AS7: Sim | AT7: Não | AU7: Não | AV7: Não | AW7: Sim | AX7: Não | AY7: Não | AZ7: Não | BA7: Não | BB7: Não | BC7: Não | BD7: Não | BE7: Não | BF7: =IF(AZ7="Não","Sim","Não") -> Sim | BG7: =IF(AZ7="NA","Sim","Não") -> Não | BH7: Não | BI7: Não cabimento | BJ7: Não cabimento / Não informado | BK7: 12a 6m | BL7: 150 | BM7: NA | BN7: NA | BO7: 12a 6m | BP7: 150 | BQ7: NA | BR7: Fechado | BS7: NA (Pena Total > 8)
A8: 7 | B8: 00970683820168260050 | C8: 1 | D8: 08/02/2017 | E8: Carla de Oliveira Pinto Ferrari | F8: Feminino | G8: 20ª Vara Criminal | H8: MARIA CRISTINA DA SILVA | I8: 1 | J8: Via Pública | K8: Feminino | L8: 34880 | M8: 21 | N8: Parda | O8: Negros, pardos e outros | P8: Não disponível | Q8: Bolsa. Dinheiro R$ 41,30 | R8: 0 | S8: 0 | T8: 0 | U8: 0 | V8: 51 porções. 12,5 g | W8: 12.5 | X8: 0 | Y8: 0 | Z8: 0 | AA8: 0 | AB8: 0 | AC8: Não | AD8: Não | AE8: Não | AF8: Não | AG8: Não | AH8: Não | AI8: Art. 33 | AJ8: Não | AK8: Preso no momento da sentença. Local de tráfico. Atitude suspeita | AL8: Procedente | AM8: Condenação por tráfico | AN8: Art. 33 | AO8: NA | AP8: Sim. Antecedentes. Natureza | AQ8: 11a 8m | AR8: Reincidência | AS8: Sim | AT8: Não | AU8: Não | AV8: Não | AW8: Sim | AX8: Não | AY8: Não | AZ8: Não | BA8: Não | BB8: Não | BC8: Não | BD8: Não | BE8: Não | BF8: =IF(AZ8="Não","Sim","Não") -> Sim | BG8: =IF(AZ8="NA","Sim","Não") -> Não | BH8: Não | BI8: Não cabimento | BJ8: Não cabimento / Não informado | BK8: 15a | BL8: 180 | BM8: NA | BN8: NA | BO8: 15a | BP8: 180 | BQ8: NA | BR8: Fechado | BS8: NA (Pena Total > 8)
A9: 8 | B9: 00554602620178260050 | C9: 0 | D9: 05/12/2017 | E9: Maria Paula Cassone Rossi | F9: Feminino | G9: 9ª Vara Criminal | H9: JONATHAN HENRIQUE DO NASCIMENTO | I9: 1 | J9: Via Pública | K9: Masculino | L9: 32973 | M9: 27 | N9: Parda | O9: Negros, pardos e outros | P9: Não disponível | Q9: Dinheiro R$ 55,00 | R9: 0 | S9: 0 | T9: 0 | U9: 0 | V9: 0 | W9: 0 | X9: 0 | Y9: 0 | Z9: 0 | AA9: 0 | AB9: 0 | AC9: Não | AD9: Não | AE9: Não | AF9: Não | AG9: Não | AH9: Não | AI9: Art. 33. Art. 35 | AJ9: Não | AK9: Local de tráfico | AL9: Parcialmente procedente | AM9: Condenação por tráfico | AN9: Art. 33 | AO9: NA | AP9: Sim. Variedade | AQ9: 5a 10m | AR9: Não | AS9: Não | AT9: Não | AU9: Não | AV9: Não | AW9: Sim | AX9: Não | AY9: Não | AZ9: Não | BA9: Não | BB9: Não | BC9: Não | BD9: Não | BE9: Não | BF9: =IF(AZ9="Não","Sim","Não") -> Sim | BG9: =IF(AZ9="NA","Sim","Não") -> Não | BH9: Não | BI9: Sim total | BJ9: Sim (total ou parcial) | BK9: 1a 11m 10d | BL9: 23.333333 | BM9: NA | BN9: NA | BO9: 1a 11m 10d | BP9: 23.333333 | BQ9: Não | BR9: Aberto | BS9: Aberto
A10: 9 | B10: 00663684520178260050 | C10: 1 | D10: 09/10/2017 | E10: Klaus Marouelli Arroyo | F10: Masculino | G10: 23ª Vara Criminal | H10: ICARO VITOR PEREIRA DE JESUS | I10: 1 | J10: Via Pública | K10: Masculino | L10: 32304 | M10: 29 | N10: Parda | O10: Negros, pardos e outros | P10: Não disponível | Q10: Estojo. Celular. Dinheiro R$ 15,00 | R10: 15 porções. 29 g | S10: 29 | T10: 11 porções. 13,2 g | U10: 13.2 | V10: 0 | W10: 0 | X10: 0 | Y10: 0 | Z10: 0 | AA10: 0 | AB10: 0 | AC10: Não | AD10: Não | AE10: Não | AF10: Não | AG10: Não | AH10: Não | AI10: Art. 33 | AJ10: Não | AK10: Confissão informal. Confissão. Local de tráfico | AL10: Procedente | AM10: Condenação por tráfico | AN10: Art. 33 | AO10: NA | AP10: Não | AQ10: 5a | AR10: Não | AS10: Não | AT10: Não | AU10: Não | AV10: Não | AW10: Sim | AX10: Não | AY10: Não | AZ10: Adolescente | BA10: Sim | BB10: Não | BC10: Não | BD10: Não | BE10: Não | BF10: =IF(AZ10="Não","Sim","Não") -> Não | BG10: =IF(AZ10="NA","Sim","Não") -> Não | BH10: Sim | BI10: Sim total | BJ10: Sim (total ou parcial) | BK10: 1a 11m 10d | BL10: 23.333333 | BM10: NA | BN10: NA | BO10: 1a 11m 10d | BP10: 23.333333 | BQ10: Não | BR10: Fechado | BS10: Fechado
A11: 10 | B11: 00583559120168260050 | C11: 1 | D11: 01/03/2017 | E11: Renata William Rached Catelli | F11: Feminino | G11: 21ª Vara Criminal | H11: THAIS HONDA SILVA | I11: 1 | J11: Via Pública | K11: Feminino | L11: 34740 | M11: 22 | N11: Parda | O11: Negros, pardos e outros | P11: Não disponível | Q11: Celular | R11: 0 | S11: 0 | T11: 7 porções. 2,6 g | U11: 2.6 | V11: 0 | W11: 0 | X11: 0 | Y11: 0 | Z11: 0 | AA11: 0 | AB11: 0 | AC11: Não | AD11: Não | AE11: Não | AF11: Não | AG11: Não | AH11: Não | AI11: Art. 33. Art. 35 | AJ11: Não | AK11: Local de tráfico. Denúncia anônima | AL11: Parcialmente procedente | AM11: Condenação por tráfico | AN11: Art. 33 | AO11: NA | AP11: Não | AQ11: 5a | AR11: Não | AS11: Não | AT11: Não | AU11: Não | AV11: Não | AW11: Sim | AX11: Não | AY11: Não | AZ11: Adolescente | BA11: Sim | BB11: Não | BC11: Não | BD11: Não | BE11: Não | BF11: =IF(AZ11="Não","Sim","Não") -> Não | BG11: =IF(AZ11="NA","Sim","Não") -> Não | BH11: Sim | BI11: Sim total | BJ11: Sim (total ou parcial) | BK11: 1a 11m 10d | BL11: 23.333333 | BM11: NA | BN11: NA | BO11: 1a 11m 10d | BP11: 23.333333 | BQ11: Não | BR11: Fechado | BS11: Fechado
A12: 11 | B12: 00763926920168260050 | C12: 1 | D12: 30/05/2017 | E12: CRISTINA ESCHER | F12: Feminino | G12: 4ª Vara Criminal | H12: EVERTON GOMES TIMOTEO | I12: 1 | J12: Via Pública | K12: Masculino | L12: 35423 | M12: 20 | N12: Parda | O12: Negros, pardos e outros | P12: Não disponível | Q12: Celular. Dinheiro R$ 80,00 | R12: 60 porções. 108,2 g | S12: 108.2 | T12: 78 porções. 63,8 g | U12: 63.8 | V12: 0 | W12: 0 | X12: 0 | Y12: 0 | Z12: 0 | AA12: 0 | AB12: Lança-perfume. 8 frascos. 44 ml | AC12: Não | AD12: Não | AE12: Não | AF12: Não | AG12: Sim | AH12: Não | AI12: Art. 33 | AJ12: Não | AK12: Preso no momento da sentença. Confissão informal | AL12: Procedente | AM12: Condenação por tráfico | AN12: Art. 33 | AO12: NA | AP12: Não | AQ12: 5a | AR12: Não | AS12: Não | AT12: Não | AU12: Não | AV12: Não | AW12: Sim | AX12: Não | AY12: Não | AZ12: Estabelecimento | BA12: Não | BB12: Não | BC12: Não | BD12: Não | BE12: Sim | BF12: =IF(AZ12="Não","Sim","Não") -> Não | BG12: =IF(AZ12="NA","Sim","Não") -> Não | BH12: Sim | BI12: Sim total | BJ12: Sim (total ou parcial) | BK12: 1a 11m 10d | BL12: 23.333333 | BM12: NA | BN12: NA | BO12: 1a 11m 10d | BP12: 23.333333 | BQ12: Não | BR12: Fechado | BS12: Fechado
A13: 12 | B13: 01036245620168260050 | C13: 1 | D13: 04/08/2017 | E13: Patrícia Álvares Cruz | F13: Feminino | G13: 9ª Vara Criminal | H13: FLÁVIO COUTINHO GOMES | I13: 1 | J13: Restaurante e afins | K13: Masculino | L13: 31567 | M13: 31 | N13: Parda | O13: Negros, pardos e outros | P13: Carapinha | Q13: Dinheiro R$ 9,00 | R13: 9 porções. 36,1 g | S13: 36.1 | T13: 9 porções. 6,8 g | U13: 6.8 | V13: 0 | W13: 0 | X13: 0 | Y13: 0 | Z13: 0 | AA13: 0 | AB13: 0 | AC13: Não | AD13: Não | AE13: Não | AF13: Não | AG13: Não | AH13: Não | AI13: Art. 33 | AJ13: Não | AK13: Local de tráfico. Preso no momento da sentença | AL13: Procedente | AM13: Condenação por tráfico | AN13: Art. 33 | AO13: NA | AP13: Sim. Variedade | AQ13: 5a 10m | AR13: Não | AS13: Não | AT13: Não | AU13: Não | AV13: Não | AW13: Sim | AX13: Não | AY13: Não | AZ13: Não | BA13: Não | BB13: Não | BC13: Não | BD13: Não | BE13: Não | BF13: =IF(AZ13="Não","Sim","Não") -> Sim | BG13: =IF(AZ13="NA","Sim","Não") -> Não | BH13: Não | BI13: Sim total | BJ13: Sim (total ou parcial) | BK13: 1a 11m 10d | BL13: 23.333333 | BM13: NA | BN13: NA | BO13: 1a 11m 10d | BP13: 23.333333 | BQ13: Não | BR13: Aberto | BS13: Aberto
A14: 13 | B14: 00292905120168260050 | C14: 1 | D14: 43017 | E14: Edison Tetsuzo Namba | F14: Masculino | G14: 16ª Vara Criminal | H14: MARILENE PINHEIRO DA ROCHA | I14: 1 | J14: Repartição Pública | K14: Feminino | L14: 25190 | M14: 48 | N14: Branca | O14: Branco e amarelo | P14: Liso | Q14: Chinelo | R14: 1 porção. 25,2 g | S14: 25.2 | T14: 0 | U14: 0 | V14: 18 porções. 7 g | W14: 7 | X14: 0 | Y14: 0 | Z14: 0 | AA14: 0 | AB14: 0 | AC14: Não | AD14: Não | AE14: Não | AF14: Não | AG14: Não | AH14: Não | AI14: Art. 33. Art. 35 | AJ14: Não | AK14: Revista Vexatória. Confissão informal | AL14: Parcialmente Procedente | AM14: Condenação por tráfico | AN14: Art. 33 | AO14: NA | AP14: Não | AQ14: 5a | AR14: Não | AS14: Não | AT14: Não | AU14: Não | AV14: Não | AW14: Sim | AX14: Não | AY14: Não | AZ14: Estabelecimento | BA14: Não | BB14: Não | BC14: Não | BD14: Não | BE14: Sim | BF14: =IF(AZ14="Não","Sim","Não") -> Não | BG14: =IF(AZ14="NA","Sim","Não") -> Não | BH14: Sim | BI14: Sim total | BJ14: Sim (total ou parcial) | BK14: 1a 11m 10d | BL14: 23.333333 | BM14: NA | BN14: NA | BO14: 1a 11m 10d | BP14: 23.333333 | BQ14: Sim | BR14: NA | BS14: NA
A15: 14 | B15: 00607505620168260050 | C15: 1 | D15: 17/03/2017 | E15: Tatiana Vieira Guerra | F15: Feminino | G15: 32ª Vara Criminal | H15: WILLEN ALVES RIBEIRO | I15: 1 | J15: Via Pública | K15: Masculino | L15: 35816 | M15: 19 | N15: Branca | O15: Branco e amarelo | P15: Outros | Q15: Dinheiro R$ 39,00 | R15: 19 porções. 24,3 g | S15: 24.3 | T15: 27 porções. 37,5 g | U15: 37.5 | V15: 20 porções. 20,5 g | W15: 20.5 | X15: 0 | Y15: 0 | Z15: 0 | AA15: 0 | AB15: 0 | AC15: Não | AD15: Não | AE15: Não | AF15: Não | AG15: Não | AH15: Não | AI15: Art. 33 | AJ15: Art. 244-B ECA | AK15: Preso no momento da sentença. Local de tráfico | AL15: Parcialmente procedente | AM15: Condenação por tráfico | AN15: Art. 33 | AO15: Não | AP15: Não | AQ15: 5a | AR15: Não | AS15: Não | AT15: Não | AU15: Não | AV15: Não | AW15: Sim | AX15: Não | AY15: Não | AZ15: Adolescente | BA15: Sim | BB15: Não | BC15: Não | BD15: Não | BE15: Não | BF15: =IF(AZ15="Não","Sim","Não") -> Não | BG15: =IF(AZ15="NA","Sim","Não") -> Não | BH15: Sim | BI15: Sim total | BJ15: Sim (total ou parcial) | BK15: 1a 11m 10d | BL15: 23.333333 | BM15: NA | BN15: NA | BO15: 1a 11m 10d | BP15: 23.333333 | BQ15: Sim | BR15: NA | BS15: NA
A16: 15 | B16: 00945836520168260050 | C16: 0 | D16: 20/03/2017 | E16: Paulo Eduardo Balbone Costa | F16: Masculino | G16: 7ª Vara Criminal | H16: MULLER DA SILVA BORGES | I16: 1 | J16: Via Pública | K16: Masculino | L16: 34440 | M16: 22 | N16: Parda | O16: Negros, pardos e outros | P16: Não disponível | Q16: Dinheiro R$ 280,00 | R16: 11 porções. 15,5 g | S16: 15.5 | T16: 71 porções. 45,6 g | U16: 45.6 | V16: 25 porções. 4,3 g | W16: 4.3 | X16: 0 | Y16: 0 | Z16: 0 | AA16: 0 | AB16: Lança-perfume. 5 frascos. 32,5 ml | AC16: Não | AD16: Não | AE16: Não | AF16: Não | AG16: Sim | AH16: Não | AI16: Art. 33. Art. 35 | AJ16: Não | AK16: Atitude suspeita. Preso no momento da sentença | AL16: Parcialmente procedente | AM16: Condenação por tráfico | AN16: Art. 33 | AO16: NA | AP16: Não | AQ16: 5a | AR16: Não | AS16: Não | AT16: Não | AU16: Não | AV16: Não | AW16: Sim | AX16: Não | AY16: Não | AZ16: Adolescente | BA16: Sim | BB16: Não | BC16: Não | BD16: Não | BE16: Não | BF16: =IF(AZ16="Não","Sim","Não") -> Não | BG16: =IF(AZ16="NA","Sim","Não") -> Não | BH16: Sim | BI16: Sim total | BJ16: Sim (total ou parcial) | BK16: 1a 11m 10d | BL16: 23.333333 | BM16: NA | BN16: NA | BO16: 1a 11m 10d | BP16: 23.333333 | BQ16: Sim | BR16: NA | BS16: NA
A17: 16 | B17: 00493201020168260050 | C17: 1 | D17: 03/04/2017 | E17: José Fernandes Freitas Neto | F17: Masculino | G17: 6ª Vara Criminal | H17: WESLEY DA SILVA COELHO | I17: 1 | J17: Via Pública | K17: Masculino | L17: 34539 | M17: 22 | N17: Branca | O17: Branco e amarelo | P17: Não disponível | Q17: Celular | R17: 520 porções. 1635 g | S17: 1635 | T17: 147 porções. 94,1 g | U17: 94.1 | V17: 496 porções. 215,4 g | W17: 215.4 | X17: 0 | Y17: 0 | Z17: 0 | AA17: 0 | AB17: 0 | AC17: Não | AD17: Não | AE17: Não | AF17: Não | AG17: Não | AH17: Não | AI17: Art. 33 | AJ17: Não | AK17: Confissão informal. Preso no momento da sentença | AL17: Procedente | AM17: Condenação por tráfico | AN17: Art. 33 | AO17: NA | AP17: Sim. Quantidade | AQ17: 5a 10m | AR17: Não | AS17: Não | AT17: Não | AU17: Não | AV17: Não | AW17: Sim | AX17: Não | AY17: Não | AZ17: Não | BA17: Não | BB17: Não | BC17: Não | BD17: Não | BE17: Não | BF17: =IF(AZ17="Não","Sim","Não") -> Sim | BG17: =IF(AZ17="NA","Sim","Não") -> Não | BH17: Não | BI17: Sim total | BJ17: Sim (total ou parcial) | BK17: 1a 11m 10d | BL17: 23.333333 | BM17: NA | BN17: NA | BO17: 1a 11m 10d | BP17: 23.333333 | BQ17: Não | BR17: Semiaberto | BS17: Semiaberto
A18: 17 | B18: 00770379420168260050 | C18: 0 | D18: 27/09/2017 | E18: Fátima Vilas Boas Cruz | F18: Feminino | G18: 17ª Vara Criminal | H18: ERICK SANTOS DE SOUZA | I18: 1 | J18: Via Pública | K18: Masculino | L18: 35908 | M18: 19 | N18: Branca | O18: Branco e amarelo | P18: Não disponível | Q18: Dinheiro R$ 200,00 | R18: 0 | S18: 0 | T18: 0 | U18: 0 | V18: 0 | W18: 0 | X18: 0 | Y18: 0 | Z18: 0 | AA18: 0 | AB18: 0 | AC18: Não | AD18: Não | AE18: Não | AF18: Não | AG18: Não | AH18: Não | AI18: Art. 33 | AJ18: Não | AK18: Local de tráfico | AL18: Procedente | AM18: Condenação por tráfico | AN18: Art. 33 | AO18: NA | AP18: Não | AQ18: 5a | AR18: Não | AS18: Não | AT18: Não | AU18: Não | AV18: Não | AW18: Sim | AX18: Não | AY18: Não | AZ18: Não | BA18: Não | BB18: Não | BC18: Não | BD18: Não | BE18: Não | BF18: =IF(AZ18="Não","Sim","Não") -> Sim | BG18: =IF(AZ18="NA","Sim","Não") -> Não | BH18: Não | BI18: Sim total | BJ18: Sim (total ou parcial) | BK18: 1a 8m | BL18: 20 | BM18: NA | BN18: NA | BO18: 1a 8m | BP18: 20 | BQ18: Sim | BR18: NA | BS18: NA
A19: 18 | B19: 00125146420168260635 | C19: 1 | D19: 01/08/2017 | E19: CRISTINA ESCHER | F19: Feminino | G19: 4ª Vara Criminal | H19: ALYSSON MARQUES DUTRA | I19: 1 | J19: Via Pública | K19: Masculino | L19: 35011 | M19: 21 | N19: Branca | O19: Branco e amarelo | P19: Não disponível | Q19: Caderno | R19: 1 sacola. 842,4 g | S19: 842.4 | T19: 0 | U19: 0 | V19: 0 | W19: 0 | X19: 0 | Y19: 0 | Z19: 0 | AA19: 0 | AB19: 0 | AC19: Não | AD19: Não | AE19: Não | AF19: Não | AG19: Não | AH19: Não | AI19: Art. 33 | AJ19: Não | AK19: Preso no momento da sentença. Atitude suspeita | AL19: Procedente | AM19: Condenação por tráfico | AN19: Art. 33 | AO19: NA | AP19: Não | AQ19: 5a | AR19: Não | AS19: Não | AT19: Não | AU19: Não | AV19: Não | AW19: Sim | AX19: Não | AY19: Não | AZ19: Não | BA19: Não | BB19: Não | BC19: Não | BD19: Não | BE19: Não | BF19: =IF(AZ19="Não","Sim","Não") -> Sim | BG19: =IF(AZ19="NA","Sim","Não") -> Não | BH19: Não | BI19: Sim total | BJ19: Sim (total ou parcial) | BK19: 1a 8m | BL19: 20 | BM19: NA | BN19: NA | BO19: 1a 8m | BP19: 20 | BQ19: Não | BR19: Semiaberto | BS19: Semiaberto
A20: 19 | B20: 00447582120178260050 | C20: 1 | D20: 09/08/2017 | E20: TERESA DE ALMEIDA RIBEIRO MAGALHAES | F20: Feminino | G20: 18ª Vara Criminal | H20: ISRAEL APARECIDO BALTAZAR | I20: 1 | J20: Via Pública | K20: Masculino | L20: 27849 | M20: 41 | N20: Parda | O20: Negros, pardos e outros | P20: Não disponível | Q20: Dinheiro R$ 30,00 | R20: 10 porções. 17,6 g | S20: 17.6 | T20: 0 | U20: 0 | V20: 0 | W20: 0 | X20: 0 | Y20: 0 | Z20: 0 | AA20: 0 | AB20: 0 | AC20: Não | AD20: Não | AE20: Não | AF20: Não | AG20: Não | AH20: Não | AI20: Art. 33 | AJ20: Não | AK20: Preso no momento da sentença. Local de tráfico | AL20: Procedente | AM20: Condenação por tráfico | AN20: Art. 33 | AO20: NA | AP20: Não | AQ20: 5a | AR20: Não | AS20: Não | AT20: Não | AU20: Não | AV20: Não | AW20: Sim | AX20: Não | AY20: Não | AZ20: Não | BA20: Não | BB20: Não | BC20: Não | BD20: Não | BE20: Não | BF20: =IF(AZ20="Não","Sim","Não") -> Sim | BG20: =IF(AZ20="NA","Sim","Não") -> Não | BH20: Não | BI20: Sim total | BJ20: Sim (total ou parcial) | BK20: 1a 8m | BL20: 20 | BM20: NA | BN20: NA | BO20: 1a 8m | BP20: 20 | BQ20: Sim | BR20: NA | BS20: NA
A21: 20 | B21: 00885193920168260050 | C21: 1 | D21: 42888 | E21: Giovana Furtado de Oliveira | F21: Feminino | G21: 24ª Vara Criminal | H21: GERSON DE JESUS SIMOES | I21: 1 | J21: Via Pública | K21: Masculino | L21: 35604 | M21: 19 | N21: Preta | O21: Negros, pardos e outros | P21: Não disponível | Q21: Dinheiro R$ 40,00 | R21: 16 porções. 64,3 g | S21: 64.3 | T21: 0 | U21: 0 | V21: 0 | W21: 0 | X21: 0 | Y21: 0 | Z21: 0 | AA21: 0 | AB21: 0 | AC21: Não | AD21: Não | AE21: Não | AF21: Não | AG21: Não | AH21: Não | AI21: Art. 33 | AJ21: Não | AK21: Confissão informal | AL21: Procedente | AM21: Condenação por tráfico | AN21: Art. 33 | AO21: NA | AP21: Não | AQ21: 5a | AR21: Não | AS21: Não | AT21: Não | AU21: Não | AV21: Não | AW21: Sim | AX21: Não | AY21: Não | AZ21: Não | BA21: Não | BB21: Não | BC21: Não | BD21: Não | BE21: Não | BF21: =IF(AZ21="Não","Sim","Não") -> Sim | BG21: =IF(AZ21="NA","Sim","Não") -> Não | BH21: Não | BI21: Sim total | BJ21: Sim (total ou parcial) | BK21: 1a 8m | BL21: 20 | BM21: NA | BN21: NA | BO21: 1a 8m | BP21: 20 | BQ21: Sim | BR21: NA | BS21: NA
A22: 21 | B22: 00316927120178260050 | C22: 1 | D22: 17/08/2017 | E22: Carla de Oliveira Pinto Ferrari | F22: Feminino | G22: 20ª Vara Criminal | H22: DANIEL ALESSANDRO BEZERRA | I22: 1 | J22: Via Pública | K22: Masculino | L22: 35651 | M22: 20 | N22: Branca | O22: Branco e amarelo | P22: Encaracolado | Q22: Dinheiro R$ 90,00 | R22: 17 porções. 66,4 g | S22: 66.4 | T22: 0 | U22: 0 | V22: 0 | W22: 0 | X22: 0 | Y22: 0 | Z22: 0 | AA22: 0 | AB22: 0 | AC22: Não | AD22: Não | AE22: Não | AF22: Não | AG22: Não | AH22: Não | AI22: Art. 33 | AJ22: Não | AK22: Local de tráfico. Confissão informal | AL22: Procedente | AM22: Condenação por tráfico | AN22: Art. 33 | AO22: NA | AP22: Não | AQ22: 5a | AR22: Não | AS22: Não | AT22: Não | AU22: Não | AV22: Não | AW22: Sim | AX22: Não | AY22: Não | AZ22: Não | BA22: Não | BB22: Não | BC22: Não | BD22: Não | BE22: Não | BF22: =IF(AZ22="Não","Sim","Não") -> Sim | BG22: =IF(AZ22="NA","Sim","Não") -> Não | BH22: Não | BI22: Sim total | BJ22: Sim (total ou parcial) | BK22: 1a 8m | BL22: 20 | BM22: NA | BN22: NA | BO22: 1a 8m | BP22: 20 | BQ22: Não | BR22: Fechado | BS22: Fechado
A23: 22 | B23: 00216280220178260050 | C23: 1 | D23: 23/05/2017 | E23: Cecilia Pinheiro da Fonseca | F23: Feminino | G23: 3ª Vara Criminal | H23: ANTONIO RODRIGUES DE LIMA | I23: 1 | J23: Residência | K23: Masculino | L23: 24436 | M23: 50 | N23: Branca | O23: Branco e amarelo | P23: Não disponível | Q23: Coldre. Arma de fogo. Munição. Caderno. Dinheiro R$ 15938,35 | R23: 201 porções. 3 tijolos. 728,2 g (total) | S23: 728.2 | T23: 0 | U23: 0 | V23: 0 | W23: 0 | X23: 0 | Y23: 0 | Z23: 0 | AA23: 0 | AB23: 0 | AC23: Não | AD23: Não | AE23: Não | AF23: Não | AG23: Não | AH23: Não | AI23: Art. 33 | AJ23: Art. 16 L10826 | AK23: Preso no momento da sentença. Atitude suspeita | AL23: Procedente | AM23: Condenação por tráfico | AN23: Art. 33 | AO23: Art. 16 L10826 (4 vezes) | AP23: Não | AQ23: 5a | AR23: Não | AS23: Não | AT23: Não | AU23: Não | AV23: Não | AW23: Sim | AX23: Não | AY23: Não | AZ23: Não | BA23: Não | BB23: Não | BC23: Não | BD23: Não | BE23: Não | BF23: =IF(AZ23="Não","Sim","Não") -> Sim | BG23: =IF(AZ23="NA","Sim","Não") -> Não | BH23: Não | BI23: Sim total | BJ23: Sim (total ou parcial) | BK23: 1a 8m | BL23: 20 | BM23: NA | BN23: 12a | BO23: 13a 8m | BP23: 164 | BQ23: NA | BR23: Fechado | BS23: NA (Pena Total > 8)
A24: 23 | B24: 00810028020168260050 | C24: 1 | D24: 03/08/2017 | E24: Antonio de Oliveira Angrisani Filho | F24: Masculino | G24: 27ª Vara Criminal | H24: FRANCISCO ANDERSON DA SILVA | I24: 1 | J24: Via Pública | K24: Masculino | L24: 35984 | M24: 19 | N24: Parda | O24: Negros, pardos e outros | P24: Não disponível | Q24: Dinheiro R$ 92,00 | R24: 27 porções. 47,7 g | S24: 47.7 | T24: 0 | U24: 0 | V24: 0 | W24: 0 | X24: 0 | Y24: 0 | Z24: 0 | AA24: 0 | AB24: 0 | AC24: Não | AD24: Não | AE24: Não | AF24: Não | AG24: Não | AH24: Não | AI24: Art. 33 | AJ24: Não | AK24: Local de tráfico. Confissão | AL24: Procedente | AM24: Condenação por tráfico | AN24: Art. 33 | AO24: NA | AP24: Não | AQ24: 5a | AR24: Não | AS24: Não | AT24: Não | AU24: Não | AV24: Não | AW24: Sim | AX24: Não | AY24: Não | AZ24: Não | BA24: Não | BB24: Não | BC24: Não | BD24: Não | BE24: Não | BF24: =IF(AZ24="Não","Sim","Não") -> Sim | BG24: =IF(AZ24="NA","Sim","Não") -> Não | BH24: Não | BI24: Sim total | BJ24: Sim (total ou parcial) | BK24: 1a 8m | BL24: 20 | BM24: NA | BN24: NA | BO24: 1a 8m | BP24: 20 | BQ24: Não | BR24: Aberto | BS24: Aberto
A25: 24 | B25: 00025180820178260635 | C25: 1 | D25: 42893 | E25: Erica Regina Colmenero Coimbra | F25: Feminino | G25: 2ª Vara Criminal | H25: JUNIOR EDOGHOTU | I25: 1 | J25: Via Pública | K25: Masculino | L25: 30297 | M25: 34 | N25: Preta | O25: Negros, pardos e outros | P25: Não disponível | Q25: Dinheiro R$ 159,75 | R25: 29 porções. 86,1 g | S25: 86.1 | T25: 0 | U25: 0 | V25: 0 | W25: 0 | X25: 0 | Y25: 0 | Z25: 0 | AA25: 0 | AB25: 0 | AC25: Não | AD25: Não | AE25: Não | AF25: Não | AG25: Não | AH25: Não | AI25: Art. 33 | AJ25: Não | AK25: Nacionalidade. Preso no momento da sentença. Local de tráfico | AL25: Procedente | AM25: Condenação por tráfico | AN25: Art. 33 | AO25: NA | AP25: Não | AQ25: 5a | AR25: Não | AS25: Não | AT25: Não | AU25: Não | AV25: Não | AW25: Sim | AX25: Não | AY25: Não | AZ25: Não | BA25: Não | BB25: Não | BC25: Não | BD25: Não | BE25: Não | BF25: =IF(AZ25="Não","Sim","Não") -> Sim | BG25: =IF(AZ25="NA","Sim","Não") -> Não | BH25: Não | BI25: Sim total | BJ25: Sim (total ou parcial) | BK25: 1a 8m | BL25: 20 | BM25: NA | BN25: NA | BO25: 1a 8m | BP25: 20 | BQ25: Não | BR25: Fechado | BS25: Fechado
